<?xml version="1.0"?>
<robot name="combined_cell">
  <link name="world"/>
  <joint name="scara_world_joint" type="fixed">
    <parent link="world"/>
    <child link="base_link"/>
    <origin xyz="-1 0 0.8" rpy="0 0 0"/>
  </joint>
  <joint name="bobby_world_joint" type="fixed">
    <parent link="world"/>
    <child link="bobby_base_link"/>
    <origin xyz="0 1.0 0.8" rpy="0 0 0"/>
  </joint>
<link
    name="base_link">
    <inertial>
      <origin
        xyz="0 0.00168973878682044 0.170983413772257"
        rpy="0 0 0" />
      <mass
        value="12.181226944499" />
      <inertia
        ixx="0.17468466573427"
        ixy="4.15759959089047E-18"
        ixz="2.94980095631604E-18"
        iyy="0.17468082989543"
        iyz="-0.000359769710444839"
        izz="0.0648964003406475" />
    </inertial>
    <visual>
      <origin
        xyz="0 0 0"
        rpy="0 0 0" />
      <geometry>
        <mesh
          filename="package://scara_robot_pkg/meshes/base_link.STL" />
      </geometry>
      <material
        name="">
        <color
          rgba="0.792156862745098 0.819607843137255 0.933333333333333 1" />
      </material>
    </visual>
    <collision>
      <origin
        xyz="0 0 0"
        rpy="0 0 0" />
      <geometry>
        <mesh
          filename="package://scara_robot_pkg/meshes/base_link.STL" />
      </geometry>
    </collision>
  </link>
  <link
    name="Link_1">
    <inertial>
      <origin
        xyz="0.315679111493496 0.00187609751792639 0.3325"
        rpy="0 0 0" />
      <mass
        value="13.501384910232" />
      <inertia
        ixx="0.0572222535179723"
        ixy="-9.50127835777007E-18"
        ixz="3.46444638425626E-18"
        iyy="0.554053995069199"
        iyz="-3.86417274088145E-18"
        izz="0.581830457702875" />
    </inertial>
    <visual>
      <origin
        xyz="0 0 0"
        rpy="0 0 0" />
      <geometry>
        <mesh
          filename="package://scara_robot_pkg/meshes/Link_1.STL" />
      </geometry>
      <material
        name="">
        <color
          rgba="0.792156862745098 0.819607843137255 0.933333333333333 1" />
      </material>
    </visual>
    <collision>
      <origin
        xyz="0 0 0"
        rpy="0 0 0" />
      <geometry>
        <mesh
          filename="package://scara_robot_pkg/meshes/Link_1.STL" />
      </geometry>
    </collision>
  </link>
  <joint
    name="Joint_1"
    type="revolute">
    <origin
      xyz="0 0 0"
      rpy="0 0 0" />
    <parent
      link="base_link" />
    <child
      link="Link_1" />
    <axis
      xyz="0 0 -1" />
    <limit
      lower="-2.53"
      upper="2.53"
      effort="0"
      velocity="7.1" />
  </joint>
  <link
    name="Link_2">
    <inertial>
      <origin
        xyz="0.190594383553034 8.92086404746806E-12 0.251287080531013"
        rpy="0 0 0" />
      <mass
        value="35.3260682085601" />
      <inertia
        ixx="0.434226114580085"
        ixy="-3.43699463108326E-11"
        ixz="0.141807287426322"
        iyy="1.54310732304715"
        iyz="-3.01122719618856E-11"
        izz="1.31387961173795" />
    </inertial>
    <visual>
      <origin
        xyz="0 0 0"
        rpy="0 0 0" />
      <geometry>
        <mesh
          filename="package://scara_robot_pkg/meshes/Link_2.STL" />
      </geometry>
      <material
        name="">
        <color
          rgba="0.792156862745098 0.819607843137255 0.933333333333333 1" />
      </material>
    </visual>
    <collision>
      <origin
        xyz="0 0 0"
        rpy="0 0 0" />
      <geometry>
        <mesh
          filename="package://scara_robot_pkg/meshes/Link_2.STL" />
      </geometry>
    </collision>
  </link>
  <joint
    name="Joint_2"
    type="revolute">
    <origin
      xyz="0.65 0.00187609751792639 0.275"
      rpy="0 0 0" />
    <parent
      link="Link_1" />
    <child
      link="Link_2" />
    <axis
      xyz="0 0 1" />
    <limit
      lower="-2.53"
      upper="2.53"
      effort="0"
      velocity="9.14" />
  </joint>
  <link
    name="Link_3">
    <inertial>
      <origin
        xyz="-2.22044604925031E-16 -2.22044604925031E-16 0.400848368011618"
        rpy="0 0 0" />
      <mass
        value="2.2590769242565" />
      <inertia
        ixx="0.119959265282819"
        ixy="-4.24291955451419E-21"
        ixz="-4.13754800332627E-20"
        iyy="0.119959265282819"
        iyz="-1.30016903886111E-19"
        izz="0.00101213903600915" />
    </inertial>
    <visual>
      <origin
        xyz="0 0 0"
        rpy="0 0 0" />
      <geometry>
        <mesh
          filename="package://scara_robot_pkg/meshes/Link_3.STL" />
      </geometry>
      <material
        name="">
        <color
          rgba="0.792156862745098 0.819607843137255 0.933333333333333 1" />
      </material>
    </visual>
    <collision>
      <origin
        xyz="0 0 0"
        rpy="0 0 0" />
      <geometry>
        <mesh
          filename="package://scara_robot_pkg/meshes/Link_3.STL" />
      </geometry>
    </collision>
  </link>
  <joint
    name="Joint_3"
    type="prismatic">
    <origin
      xyz="0.6 0 0.886978614262261"
      rpy="3.14159265358979 0 0" />
    <parent
      link="Link_2" />
    <child
      link="Link_3" />
    <axis
      xyz="0 0 -1" />
    <limit
      lower="-0.45"
      upper="0"
      effort="0"
      velocity="2.24" />
  </joint>
  <link
    name="Link_4">
    <inertial>
      <origin
        xyz="-2.22044604925031E-16 0 -0.00126874999999993"
        rpy="0 0 0" />
      <mass
        value="5.61232437594433E-05" />
      <inertia
        ixx="1.50285331365377E-10"
        ixy="-1.05664104903945E-26"
        ixz="-9.29971021358974E-30"
        iyy="1.50285331365377E-10"
        iyz="8.77391512839114E-27"
        izz="1.85627628734358E-10" />
    </inertial>
    <visual>
      <origin
        xyz="0 0 0"
        rpy="0 0 0" />
      <geometry>
        <mesh
          filename="package://scara_robot_pkg/meshes/Link_4.STL" />
      </geometry>
      <material
        name="">
        <color
          rgba="0.792156862745098 0.819607843137255 0.933333333333333 1" />
      </material>
    </visual>
    <collision>
      <origin
        xyz="0 0 0"
        rpy="0 0 0" />
      <geometry>
        <mesh
          filename="package://scara_robot_pkg/meshes/Link_4.STL" />
      </geometry>
    </collision>
  </link>
  <joint
    name="Joint_4"
    type="revolute">
    <origin
      xyz="0 0 0.8335"
      rpy="0 0 0" />
    <parent
      link="Link_3" />
    <child
      link="Link_4" />
    <axis
      xyz="0 0 -1" />
    <limit
      lower="-6.98"
      upper="6.98"
      effort="0"
      velocity="29.7" />
  </joint>
<link
    name="bobby_base_link">
    <inertial>
      <origin
        xyz="-6.93889390390723E-18 -8.67361737988404E-18 0.00903009179983284"
        rpy="0 0 0" />
      <mass
        value="0.168853238991176" />
      <inertia
        ixx="0.000188908722369925"
        ixy="-5.7902642878712E-21"
        ixz="4.9831826221772E-21"
        iyy="0.000188908722369926"
        iyz="-1.68425616825269E-20"
        izz="0.000347553571686864" />
    </inertial>
    <visual>
      <origin
        xyz="0 0 0"
        rpy="0 0 0" />
      <geometry>
        <mesh
          filename="package://bobby/meshes/base_link.STL" />
      </geometry>
      <material
        name="technikum_grau">
        <color
          rgba="0.447 0.471 0.478 1" />
      </material>
    </visual>
    <collision>
      <origin
        xyz="0 0 0"
        rpy="0 0 0" />
      <geometry>
        <mesh
          filename="package://bobby/meshes/base_link.STL" />
      </geometry>
    </collision>
  </link>
  <link
    name="bobby_link_1">
    <inertial>
      <origin
        xyz="-2.15652112519824E-07 0.0107734448420019 0.109157368914489"
        rpy="0 0 0" />
      <mass
        value="0.19567354215977" />
      <inertia
        ixx="0.00036569472644765"
        ixy="3.25955315579442E-10"
        ixz="1.75361435601525E-09"
        iyy="0.000399646100597159"
        iyz="5.8509284245807E-07"
        izz="0.000228564395108126" />
    </inertial>
    <visual>
      <origin
        xyz="0 0 0"
        rpy="0 0 0" />
      <geometry>
        <mesh
          filename="package://bobby/meshes/link_1.STL" />
      </geometry>
      <material
        name="technikum_grau">
        <color
          rgba="0.447 0.471 0.478 1" />
      </material>
    </visual>
    <collision>
      <origin
        xyz="0 0 0"
        rpy="0 0 0" />
      <geometry>
        <mesh
          filename="package://bobby/meshes/link_1.STL" />
      </geometry>
    </collision>
  </link>
  <joint
    name="joint_1"
    type="revolute">
    <origin
      xyz="0 0 0"
      rpy="0 0 0" />
    <parent
      link="bobby_base_link" />
    <child
      link="bobby_link_1" />
    <axis
      xyz="0 0 1" />
    <limit
      lower="-3.14"
      upper="3.14"
      effort="80"
      velocity="1.5" />
    <dynamics
      damping="0.2" />
  </joint>
  <link
    name="bobby_link_2">
    <inertial>
      <origin
        xyz="-1.60868451060114E-08 -0.114041602248857 0.132749921878617"
        rpy="0 0 0" />
      <mass
        value="0.277035202004268" />
      <inertia
        ixx="0.00289478457764281"
        ixy="-1.24048336188053E-09"
        ixz="1.22368569354385E-09"
        iyy="0.000189976410051189"
        iyz="7.94253254153287E-05"
        izz="0.00286373711090803" />
    </inertial>
    <visual>
      <origin
        xyz="0 0 0"
        rpy="0 0 0" />
      <geometry>
        <mesh
          filename="package://bobby/meshes/link_2.STL" />
      </geometry>
      <material
        name="technikum_grau">
        <color
          rgba="0.447 0.471 0.478 1" />
      </material>
    </visual>
    <collision>
      <origin
        xyz="0 0 0"
        rpy="0 0 0" />
      <geometry>
        <mesh
          filename="package://bobby/meshes/link_2.STL" />
      </geometry>
    </collision>
  </link>
  <joint
    name="joint_2"
    type="revolute">
    <origin
      xyz="0 0 0.11"
      rpy="-1.5707963267949 0 0" />
    <parent
      link="bobby_link_1" />
    <child
      link="bobby_link_2" />
    <axis
      xyz="0 0 1" />
    <limit
      lower="-2"
      upper="2"
      effort="60"
      velocity="1.5" />
    <dynamics
      damping="0.15" />
  </joint>
  <link
    name="bobby_link_3">
    <inertial>
      <origin
        xyz="-4.46835846875521E-07 -0.021332834225784 0.336950985055037"
        rpy="0 0 0" />
      <mass
        value="0.104323112073039" />
      <inertia
        ixx="0.000172552084016025"
        ixy="1.24275852401533E-10"
        ixz="-1.16774421742549E-10"
        iyy="5.69008711097092E-05"
        iyz="6.87130934985452E-06"
        izz="0.000165314592613562" />
    </inertial>
    <visual>
      <origin
        xyz="0 0 0"
        rpy="0 0 0" />
      <geometry>
        <mesh
          filename="package://bobby/meshes/link_3.STL" />
      </geometry>
      <material
        name="technikum_grau">
        <color
          rgba="0.447 0.471 0.478 1" />
      </material>
    </visual>
    <collision>
      <origin
        xyz="0 0 0"
        rpy="0 0 0" />
      <geometry>
        <mesh
          filename="package://bobby/meshes/link_3.STL" />
      </geometry>
    </collision>
  </link>
  <joint
    name="joint_3"
    type="revolute">
    <origin
      xyz="0 0 0.135"
      rpy="1.5707963267949 0 0" />
    <parent
      link="bobby_link_2" />
    <child
      link="bobby_link_3" />
    <axis
      xyz="0 0 -1" />
    <limit
      lower="-2.5"
      upper="2.5"
      effort="40"
      velocity="2" />
    <dynamics
      damping="0.1" />
  </joint>
  <link
    name="bobby_link_4">
    <inertial>
      <origin
        xyz="-7.35759638319233E-08 0.0214973669189123 0.127010226840711"
        rpy="0 0 0" />
      <mass
        value="0.104021403954901" />
      <inertia
        ixx="0.000172095228395825"
        ixy="5.22139873101622E-11"
        ixz="-7.41592698784508E-11"
        iyy="5.67379606621111E-05"
        iyz="-6.68507413422721E-06"
        izz="0.000164961710546567" />
    </inertial>
    <visual>
      <origin
        xyz="0 0 0"
        rpy="0 0 0" />
      <geometry>
        <mesh
          filename="package://bobby/meshes/link_4.STL" />
      </geometry>
      <material
        name="technikum_grau">
        <color
          rgba="0.447 0.471 0.478 1" />
      </material>
    </visual>
    <collision>
      <origin
        xyz="0 0 0"
        rpy="0 0 0" />
      <geometry>
        <mesh
          filename="package://bobby/meshes/link_4.STL" />
      </geometry>
    </collision>
  </link>
  <joint
    name="joint_4"
    type="revolute">
    <origin
      xyz="0 0.000262563950500366 0.34"
      rpy="1.5707963267949 0 0" />
    <parent
      link="bobby_link_3" />
    <child
      link="bobby_link_4" />
    <axis
      xyz="0 0 -1" />
    <limit
      lower="-3.14"
      upper="3.14"
      effort="20"
      velocity="3" />
    <dynamics
      damping="0.05" />
  </joint>
  <link
    name="bobby_link_5">
    <inertial>
      <origin
        xyz="-7.72747078825464E-09 0.0118852064404541 0.124078122231419"
        rpy="0 0 0" />
      <mass
        value="0.0635312499775335" />
      <inertia
        ixx="5.3078651829625E-05"
        ixy="-2.16462957974075E-11"
        ixz="-2.18923663634894E-11"
        iyy="2.59966766341151E-05"
        iyz="-4.43828682190682E-06"
        izz="4.66910033521407E-05" />
    </inertial>
    <visual>
      <origin
        xyz="0 0 0"
        rpy="0 0 0" />
      <geometry>
        <mesh
          filename="package://bobby/meshes/link_5.STL" />
      </geometry>
      <material
        name="technikum_grau">
        <color
          rgba="0.447 0.471 0.478 1" />
      </material>
    </visual>
    <collision>
      <origin
        xyz="0 0 0"
        rpy="0 0 0" />
      <geometry>
        <mesh
          filename="package://bobby/meshes/link_5.STL" />
      </geometry>
    </collision>
  </link>
  <joint
    name="joint_5"
    type="revolute">
    <origin
      xyz="0 -0.000178126389957234 0.13"
      rpy="-1.5707963267949 0 0" />
    <parent
      link="bobby_link_4" />
    <child
      link="bobby_link_5" />
    <axis
      xyz="0 0 -1" />
    <limit
      lower="-2"
      upper="2"
      effort="15"
      velocity="3.5" />
    <dynamics
      damping="0.05" />
  </joint>
  <link
    name="bobby_link_6">
    <inertial>
      <origin
        xyz="-9.09411435046081E-14 -4.99933427988708E-13 0.00443393044915172"
        rpy="0 0 0" />
      <mass
        value="0.0247796339074861" />
      <inertia
        ixx="5.79719477129161E-06"
        ixy="1.69371937738642E-21"
        ixz="-1.74584771115396E-21"
        iyy="5.61206813663289E-06"
        iyz="1.25047386620786E-20"
        izz="8.2664668127508E-06" />
    </inertial>
    <visual>
      <origin xyz="0 0 -0.005" rpy="0 0 0"/>
      <geometry><mesh filename="package://bobby/meshes/link_6.STL" scale="0.001 0.001 0.001"/></geometry>
      <material name="technikum_grau"><color rgba="0.447 0.471 0.478 1"/></material>
    </visual>
    <collision>
      <origin xyz="0 0 -0.005" rpy="0 0 0"/>
      <geometry><mesh filename="package://bobby/meshes/link_6.STL" scale="0.001 0.001 0.001"/></geometry>
    </collision>
  </link>
  <joint
    name="joint_6"
    type="revolute">
    <origin
      xyz="0 0.0700000000012193 0.129999999999002"
      rpy="-1.57079632679489 0 0" />
    <parent
      link="bobby_link_5" />
    <child
      link="bobby_link_6" />
    <axis
      xyz="0 0 -1" />
    <limit
      lower="-3.14"
      upper="3.14"
      effort="10"
      velocity="4" />
    <dynamics
      damping="0.03" />
  </joint>
  
  
  <link name="bobby_gripper_flange">
    <inertial>
      <origin xyz="0 0 0.005" rpy="0 0 0"/>
      <mass value="0.2"/>
      <inertia ixx="6.782e-05" ixy="0" ixz="0" iyy="6.782e-05" iyz="0" izz="1.323e-04"/>
    </inertial>
    <visual>
      <origin xyz="0 0 0.005" rpy="0 0 0"/>
      <geometry><mesh filename="package://bobby/meshes/gripper_flange.STL" scale="0.001 0.001 0.001"/></geometry>
      <material name="technikum_blau"><color rgba="0 0.392 0.612 1"/></material>
    </visual>
    <collision>
      <origin xyz="0 0 0.005" rpy="0 0 0"/>
      <geometry><mesh filename="package://bobby/meshes/gripper_flange.STL" scale="0.001 0.001 0.001"/></geometry>
    </collision>
  </link>
  <joint name="gripper_flange_joint" type="fixed">
    <origin xyz="0 0 0.01" rpy="0 0 0"/>
    <parent link="bobby_link_6"/>
    <child link="bobby_gripper_flange"/>
    <axis xyz="0 0 0"/>
  </joint>

  
  <link name="bobby_gripper_base">
    <inertial>
      <origin xyz="0 0 0.015" rpy="0 0 0"/>
      <mass value="0.028"/>
      <inertia ixx="2.333e-06" ixy="0" ixz="0" iyy="2.357e-05" iyz="0" izz="2.543e-05"/>
    </inertial>
    <visual>
      <origin xyz="0 0 0.015" rpy="0 0 0"/>
      <geometry><mesh filename="package://bobby/meshes/gripper_base.STL" scale="0.001 0.001 0.001"/></geometry>
      <material name="technikum_blau"/>
    </visual>
    <collision>
      <origin xyz="0 0 0.015" rpy="0 0 0"/>
      <geometry><mesh filename="package://bobby/meshes/gripper_base.STL" scale="0.001 0.001 0.001"/></geometry>
    </collision>
  </link>
  <joint name="gripper_base_joint" type="fixed">
    <origin xyz="0 0 0" rpy="0 0 0"/>
    <parent link="bobby_gripper_flange"/>
    <child link="bobby_gripper_base"/>
    <axis xyz="0 0 0"/>
  </joint>

  
  <link name="bobby_finger_left">
    <inertial>
      <origin xyz="0 0 0.045" rpy="0 0 0"/>
      <mass value="0.05"/>
      <inertia ixx="3.542e-05" ixy="0" ixz="0" iyy="3.417e-05" iyz="0" izz="2.083e-06"/>
    </inertial>
    <visual>
      <origin xyz="0 0 0.045" rpy="0 0 0"/>
      <geometry><mesh filename="package://bobby/meshes/finger_left.STL" scale="0.001 0.001 0.001"/></geometry>
      <material name="technikum_gruen"><color rgba="0.545 0.702 0.114 1"/></material>
    </visual>
    <collision>
      <origin xyz="0 0 0.045" rpy="0 0 0"/>
      <geometry><mesh filename="package://bobby/meshes/finger_left.STL" scale="0.001 0.001 0.001"/></geometry>
    </collision>
  </link>
  <joint name="finger_left_joint" type="prismatic">
    <origin xyz="0.006 0 0.021" rpy="0 0 0"/>
    <parent link="bobby_gripper_base"/>
    <child link="bobby_finger_left"/>
    <axis xyz="1 0 0"/>
    <limit lower="0" upper="0.04" effort="50" velocity="0.1"/>
  </joint>

  
  <link name="bobby_finger_right">
    <inertial>
      <origin xyz="0 0 0.045" rpy="0 0 0"/>
      <mass value="0.05"/>
      <inertia ixx="3.542e-05" ixy="0" ixz="0" iyy="3.417e-05" iyz="0" izz="2.083e-06"/>
    </inertial>
    <visual>
      <origin xyz="0 0 0.045" rpy="0 0 0"/>
      <geometry><mesh filename="package://bobby/meshes/finger_left.STL" scale="0.001 0.001 0.001"/></geometry>
      <material name="technikum_gruen"><color rgba="0.545 0.702 0.114 1"/></material>
    </visual>
    <collision>
      <origin xyz="0 0 0.045" rpy="0 0 0"/>
      <geometry><mesh filename="package://bobby/meshes/finger_left.STL" scale="0.001 0.001 0.001"/></geometry>
    </collision>
  </link>
  <joint name="finger_right_joint" type="prismatic">
    <origin xyz="-0.006 0 0.021" rpy="0 0 0"/>
    <parent link="bobby_gripper_base"/>
    <child link="bobby_finger_right"/>
    <axis xyz="1 0 0"/>
    <limit lower="-0.04" upper="0" effort="50" velocity="0.1"/>
    <mimic joint="finger_left_joint" multiplier="-1" offset="0"/>
  </joint>

  
  <link name="bobby_TCP"/>
  <joint name="TCP_joint" type="fixed">
    <origin xyz="0 0 0.111" rpy="0 0 0"/>
    <parent link="bobby_gripper_base"/>
    <child link="bobby_TCP"/>
    <axis xyz="0 0 0"/>
  </joint>
  <ros2_control name="CombinedGazeboSystem" type="system">
    <hardware>
      <plugin>gazebo_ros2_control/GazeboSystem</plugin>
    </hardware>
    <joint name="Joint_1">
      <command_interface name="position">
        <param name="min">-2.5299</param>
        <param name="max">2.5299</param>
      </command_interface>
      <state_interface name="position">
        <param name="initial_value">0.6849</param>
      </state_interface>
      <state_interface name="velocity"/>
    </joint>
    <joint name="Joint_2">
      <command_interface name="position">
        <param name="min">-2.5299</param>
        <param name="max">2.5299</param>
      </command_interface>
      <state_interface name="position">
        <param name="initial_value">-2.5299</param>
      </state_interface>
      <state_interface name="velocity"/>
    </joint>
    <joint name="Joint_3">
      <command_interface name="position">
        <param name="min">-0.45</param>
        <param name="max">0.0</param>
      </command_interface>
      <state_interface name="position">
        <param name="initial_value">0.0</param>
      </state_interface>
      <state_interface name="velocity"/>
    </joint>
    <joint name="Joint_4">
      <command_interface name="position">
        <param name="min">-6.98</param>
        <param name="max">6.98</param>
      </command_interface>
      <state_interface name="position">
        <param name="initial_value">0.0</param>
      </state_interface>
      <state_interface name="velocity"/>
    </joint>
    <joint name="joint_1">
      <command_interface name="position"/>
      <state_interface name="position">
        <param name="initial_value">0.0</param>
      </state_interface>
      <state_interface name="velocity"/>
    </joint>
    <joint name="joint_2">
      <command_interface name="position"/>
      <state_interface name="position">
        <param name="initial_value">0.0</param>
      </state_interface>
      <state_interface name="velocity"/>
    </joint>
    <joint name="joint_3">
      <command_interface name="position"/>
      <state_interface name="position">
        <param name="initial_value">0.0</param>
      </state_interface>
      <state_interface name="velocity"/>
    </joint>
    <joint name="joint_4">
      <command_interface name="position"/>
      <state_interface name="position">
        <param name="initial_value">0.0</param>
      </state_interface>
      <state_interface name="velocity"/>
    </joint>
    <joint name="joint_5">
      <command_interface name="position"/>
      <state_interface name="position">
        <param name="initial_value">0.0</param>
      </state_interface>
      <state_interface name="velocity"/>
    </joint>
    <joint name="joint_6">
      <command_interface name="position"/>
      <state_interface name="position">
        <param name="initial_value">0.0</param>
      </state_interface>
      <state_interface name="velocity"/>
    </joint>
    <joint name="finger_left_joint">
      <command_interface name="position"/>
      <state_interface name="position">
        <param name="initial_value">0.02</param>
      </state_interface>
      <state_interface name="velocity"/>
    </joint>
  </ros2_control>
  <gazebo>
    <plugin filename="libgazebo_ros2_control.so" name="combined_gazebo_ros2_control">
      <robot_param>robot_description</robot_param>
      <robot_param_node>robot_state_publisher</robot_param_node>
      <parameters>__COMBINED_CONTROLLERS_YAML__</parameters>
    </plugin>
  </gazebo>
</robot>