<?xml version="1.0" encoding="utf-8"?>
<!-- This URDF was automatically created by SolidWorks to URDF Exporter! Originally created by Stephen Brawner (brawner@gmail.com) 
     Commit Version: 1.6.0-4-g7f85cfe  Build Version: 1.6.7995.38578
     For more information, please see http://wiki.ros.org/sw_urdf_exporter -->
<robot
  name="Scara Assembly1">
  <link
    name="base_link">
    <inertial>
      <origin
        xyz="0 0.00168973878682044 0.170983413772257"
        rpy="0 0 0" />
      <mass
        value="12.181226944499" />
      <inertia
        ixx="0.17468466573427"
        ixy="4.15759959089047E-18"
        ixz="2.94980095631604E-18"
        iyy="0.17468082989543"
        iyz="-0.000359769710444839"
        izz="0.0648964003406475" />
    </inertial>
    <visual>
      <origin
        xyz="0 0 0"
        rpy="0 0 0" />
      <geometry>
        <mesh
          filename="package://scara_robot_pkg/meshes/base_link.STL" />
      </geometry>
      <material
        name="">
        <color
          rgba="0.792156862745098 0.819607843137255 0.933333333333333 1" />
      </material>
    </visual>
    <collision>
      <origin
        xyz="0 0 0"
        rpy="0 0 0" />
      <geometry>
        <mesh
          filename="package://scara_robot_pkg/meshes/base_link.STL" />
      </geometry>
    </collision>
  </link>
  <link
    name="Link_1">
    <inertial>
      <origin
        xyz="0.315679111493496 0.00187609751792639 0.3325"
        rpy="0 0 0" />
      <mass
        value="13.501384910232" />
      <inertia
        ixx="0.0572222535179723"
        ixy="-9.50127835777007E-18"
        ixz="3.46444638425626E-18"
        iyy="0.554053995069199"
        iyz="-3.86417274088145E-18"
        izz="0.581830457702875" />
    </inertial>
    <visual>
      <origin
        xyz="0 0 0"
        rpy="0 0 0" />
      <geometry>
        <mesh
          filename="package://scara_robot_pkg/meshes/Link_1.STL" />
      </geometry>
      <material
        name="">
        <color
          rgba="0.792156862745098 0.819607843137255 0.933333333333333 1" />
      </material>
    </visual>
    <collision>
      <origin
        xyz="0 0 0"
        rpy="0 0 0" />
      <geometry>
        <mesh
          filename="package://scara_robot_pkg/meshes/Link_1.STL" />
      </geometry>
    </collision>
  </link>
  <joint
    name="Joint_1"
    type="revolute">
    <origin
      xyz="0 0 0"
      rpy="0 0 0" />
    <parent
      link="base_link" />
    <child
      link="Link_1" />
    <axis
      xyz="0 0 -1" />
    <limit
      lower="-2.53"
      upper="2.53"
      effort="0"
      velocity="7.1" />
  </joint>
  <link
    name="Link_2">
    <inertial>
      <origin
        xyz="0.190594383553034 8.92086404746806E-12 0.251287080531013"
        rpy="0 0 0" />
      <mass
        value="35.3260682085601" />
      <inertia
        ixx="0.434226114580085"
        ixy="-3.43699463108326E-11"
        ixz="0.141807287426322"
        iyy="1.54310732304715"
        iyz="-3.01122719618856E-11"
        izz="1.31387961173795" />
    </inertial>
    <visual>
      <origin
        xyz="0 0 0"
        rpy="0 0 0" />
      <geometry>
        <mesh
          filename="package://scara_robot_pkg/meshes/Link_2.STL" />
      </geometry>
      <material
        name="">
        <color
          rgba="0.792156862745098 0.819607843137255 0.933333333333333 1" />
      </material>
    </visual>
    <collision>
      <origin
        xyz="0 0 0"
        rpy="0 0 0" />
      <geometry>
        <mesh
          filename="package://scara_robot_pkg/meshes/Link_2.STL" />
      </geometry>
    </collision>
  </link>
  <joint
    name="Joint_2"
    type="revolute">
    <origin
      xyz="0.65 0.00187609751792639 0.275"
      rpy="0 0 0" />
    <parent
      link="Link_1" />
    <child
      link="Link_2" />
    <axis
      xyz="0 0 1" />
    <limit
      lower="-2.53"
      upper="2.53"
      effort="0"
      velocity="9.14" />
  </joint>
  <link
    name="Link_3">
    <inertial>
      <origin
        xyz="-2.22044604925031E-16 -2.22044604925031E-16 0.400848368011618"
        rpy="0 0 0" />
      <mass
        value="2.2590769242565" />
      <inertia
        ixx="0.119959265282819"
        ixy="-4.24291955451419E-21"
        ixz="-4.13754800332627E-20"
        iyy="0.119959265282819"
        iyz="-1.30016903886111E-19"
        izz="0.00101213903600915" />
    </inertial>
    <visual>
      <origin
        xyz="0 0 0"
        rpy="0 0 0" />
      <geometry>
        <mesh
          filename="package://scara_robot_pkg/meshes/Link_3.STL" />
      </geometry>
      <material
        name="">
        <color
          rgba="0.792156862745098 0.819607843137255 0.933333333333333 1" />
      </material>
    </visual>
    <collision>
      <origin
        xyz="0 0 0"
        rpy="0 0 0" />
      <geometry>
        <mesh
          filename="package://scara_robot_pkg/meshes/Link_3.STL" />
      </geometry>
    </collision>
  </link>
  <joint
    name="Joint_3"
    type="prismatic">
    <origin
      xyz="0.6 0 0.886978614262261"
      rpy="3.14159265358979 0 0" />
    <parent
      link="Link_2" />
    <child
      link="Link_3" />
    <axis
      xyz="0 0 -1" />
    <limit
      lower="-0.45"
      upper="0"
      effort="0"
      velocity="2.24" />
  </joint>
  <link
    name="Link_4">
    <inertial>
      <origin
        xyz="-2.22044604925031E-16 0 -0.00126874999999993"
        rpy="0 0 0" />
      <mass
        value="5.61232437594433E-05" />
      <inertia
        ixx="1.50285331365377E-10"
        ixy="-1.05664104903945E-26"
        ixz="-9.29971021358974E-30"
        iyy="1.50285331365377E-10"
        iyz="8.77391512839114E-27"
        izz="1.85627628734358E-10" />
    </inertial>
    <visual>
      <origin
        xyz="0 0 0"
        rpy="0 0 0" />
      <geometry>
        <mesh
          filename="package://scara_robot_pkg/meshes/Link_4.STL" />
      </geometry>
      <material
        name="">
        <color
          rgba="0.792156862745098 0.819607843137255 0.933333333333333 1" />
      </material>
    </visual>
    <collision>
      <origin
        xyz="0 0 0"
        rpy="0 0 0" />
      <geometry>
        <mesh
          filename="package://scara_robot_pkg/meshes/Link_4.STL" />
      </geometry>
    </collision>
  </link>
  <joint
    name="Joint_4"
    type="revolute">
    <origin
      xyz="0 0 0.8335"
      rpy="0 0 0" />
    <parent
      link="Link_3" />
    <child
      link="Link_4" />
    <axis
      xyz="0 0 -1" />
    <limit
      lower="-6.98"
      upper="6.98"
      effort="0"
      velocity="29.7" />
  </joint>
</robot>